<?xml version="1.0" ?>
<!-- =================================================================================== -->
<!-- |    This document was autogenerated by xacro from denso_robot.urdf.xacro         | -->
<!-- |    EDITING THIS FILE BY HAND IS NOT RECOMMENDED                                 | -->
<!-- =================================================================================== -->
<robot name="denso_robot">
  <!-- create link fixed to the "world" -->
  <link name="world"/>
  <!-- LINKS -->
  <!-- base link -->
  <link name="base_link">
    <inertial>
      <origin rpy="0 0 0" xyz="0 0 0"/>
      <mass value="1"/>
      <inertia ixx="1" ixy="0.0" ixz="0.0" iyy="1" iyz="0.0" izz="1"/>
    </inertial>
    <visual>
      <origin rpy="0 0 0" xyz="0 0 0"/>
      <geometry>
        <mesh filename="package://denso_robot_description/meshes/denso_robot/visual/base_link.dae"/>
      </geometry>
    </visual>
    <collision>
      <origin rpy="0 0 0" xyz="0 0 0"/>
      <geometry>
        <mesh filename="package://denso_robot_description/meshes/denso_robot/visual/base_link.dae"/>
      </geometry>
    </collision>
  </link>
  <!-- link 1 -->
  <link name="link1">
    <inertial>
      <origin rpy="0 0 0" xyz="0 0 0"/>
      <mass value="1"/>
      <inertia ixx="1" ixy="0.0" ixz="0.0" iyy="1" iyz="0.0" izz="1"/>
    </inertial>
    <visual>
      <origin rpy="0 0 0" xyz="0 0 0"/>
      <geometry>
        <mesh filename="package://denso_robot_description/meshes/denso_robot/visual/J1.dae"/>
      </geometry>
    </visual>
    <collision>
      <origin rpy="0 0 0" xyz="0 0 0"/>
      <geometry>
        <mesh filename="package://denso_robot_description/meshes/denso_robot/visual/J1.dae"/>
      </geometry>
    </collision>
  </link>
  <!-- link 2 -->
  <link name="link2">
    <inertial>
      <origin rpy="0 0 0" xyz="0 0 0"/>
      <mass value="1"/>
      <inertia ixx="1" ixy="0.0" ixz="0.0" iyy="1" iyz="0.0" izz="1"/>
    </inertial>
    <visual>
      <origin rpy="0 0 0" xyz="0 0 0"/>
      <geometry>
        <mesh filename="package://denso_robot_description/meshes/denso_robot/visual/J2.dae"/>
      </geometry>
    </visual>
    <collision>
      <origin rpy="0 0 0" xyz="0 0 0"/>
      <geometry>
        <mesh filename="package://denso_robot_description/meshes/denso_robot/visual/J2.dae"/>
      </geometry>
    </collision>
  </link>
  <!-- link 3 -->
  <link name="link3">
    <inertial>
      <origin rpy="0 0 0" xyz="0 0 0"/>
      <mass value="1"/>
      <inertia ixx="1" ixy="0.0" ixz="0.0" iyy="1" iyz="0.0" izz="1"/>
    </inertial>
    <visual>
      <origin rpy="0 0 0" xyz="0 0 0"/>
      <geometry>
        <mesh filename="package://denso_robot_description/meshes/denso_robot/visual/J3.dae"/>
      </geometry>
    </visual>
    <collision>
      <origin rpy="0 0 0" xyz="0 0 0"/>
      <geometry>
        <mesh filename="package://denso_robot_description/meshes/denso_robot/visual/J3.dae"/>
      </geometry>
    </collision>
  </link>
  <!-- link 4 -->
  <link name="link4">
    <inertial>
      <origin rpy="0 0 0" xyz="0 0 0"/>
      <mass value="1"/>
      <inertia ixx="1" ixy="0.0" ixz="0.0" iyy="1" iyz="0.0" izz="1"/>
    </inertial>
    <visual>
      <origin rpy="0 0 0" xyz="0 0 0"/>
      <geometry>
        <mesh filename="package://denso_robot_description/meshes/denso_robot/visual/J4.dae"/>
      </geometry>
    </visual>
    <collision>
      <origin rpy="0 0 0" xyz="0 0 0"/>
      <geometry>
        <mesh filename="package://denso_robot_description/meshes/denso_robot/visual/J4.dae"/>
      </geometry>
    </collision>
  </link>
  <!-- link 5 -->
  <link name="link5">
    <inertial>
      <origin rpy="0 0 0" xyz="0 0 0"/>
      <mass value="1"/>
      <inertia ixx="1" ixy="0.0" ixz="0.0" iyy="1" iyz="0.0" izz="1"/>
    </inertial>
    <visual>
      <origin rpy="0 0 0" xyz="0 0 0"/>
      <geometry>
        <mesh filename="package://denso_robot_description/meshes/denso_robot/visual/J5.dae"/>
      </geometry>
    </visual>
    <collision>
      <origin rpy="0 0 0" xyz="0 0 0"/>
      <geometry>
        <mesh filename="package://denso_robot_description/meshes/denso_robot/visual/J5.dae"/>
      </geometry>
    </collision>
  </link>
  <!-- link 6 -->
  <link name="link6">
    <inertial>
      <origin rpy="0 0 0" xyz="0 0 0"/>
      <mass value="1"/>
      <inertia ixx="1" ixy="0.0" ixz="0.0" iyy="1" iyz="0.0" izz="1"/>
    </inertial>
    <visual>
      <origin rpy="0 0 0" xyz="0 0 0"/>
      <geometry>
        <mesh filename="package://denso_robot_description/meshes/denso_robot/visual/J6.dae"/>
      </geometry>
    </visual>
    <collision>
      <origin rpy="0 0 0" xyz="0 0 0"/>
      <geometry>
        <mesh filename="package://denso_robot_description/meshes/denso_robot/visual/J6.dae"/>
      </geometry>
    </collision>
  </link>
  <!-- All-zero tool frame. This frame should correspond to the TOOL frame of the robot's controller.) -->
  <link name="tool0"/>
  <!-- tool link -->
  <!-- END LINKS -->
  <!-- JOINTS -->
  <!-- base_joint fixes base_link to the environment -->
  <joint name="base_joint" type="fixed">
    <origin rpy="0 0 0" xyz="0 0 0"/>
    <parent link="world"/>
    <child link="base_link"/>
  </joint>
  <!-- joint 1 -->
  <joint name="joint1" type="revolute">
    <origin rpy="0 0 0" xyz="0 0 0.197500"/>
    <parent link="base_link"/>
    <child link="link1"/>
    <axis xyz="0 0 1"/>
    <limit effort="1000" lower="-2.9670597283903604" upper="2.9670597283903604" velocity="6.283185307179586"/>
    <dynamics damping="0.7" friction="0.0"/>
  </joint>
  <!-- joint 2 -->
  <joint name="joint2" type="revolute">
    <origin rpy="0 0 0" xyz="0.03 0 0.1975"/>
    <parent link="link1"/>
    <child link="link2"/>
    <axis xyz="0 1 0"/>
    <limit effort="1000" lower="-1.7453292519943295" upper="2.356194490192345" velocity="5.235987755982989"/>
    <dynamics damping="0.7" friction="0.0"/>
  </joint>
  <!-- joint 3 -->
  <joint name="joint3" type="revolute">
    <origin rpy="0 0 0" xyz="0 0 0.445"/>
    <parent link="link2"/>
    <child link="link3"/>
    <axis xyz="0 1 0"/>
    <limit effort="1000" lower="-2.3736477827122884" upper="2.670353755551324" velocity="7.120943348136865"/>
    <dynamics damping="0.7" friction="0.0"/>
  </joint>
  <!-- joint 4 -->
  <joint name="joint4" type="revolute">
    <origin rpy="0 0 0" xyz="-0.02 0 0.287"/>
    <parent link="link3"/>
    <child link="link4"/>
    <axis xyz="0 0 1"/>
    <limit effort="1000" lower="-4.71238898038469" upper="4.71238898038469" velocity="9.42477796076938"/>
    <dynamics damping="0.7" friction="0.0"/>
  </joint>
  <!-- joint 5 -->
  <joint name="joint5" type="revolute">
    <origin rpy="0 0 0" xyz="0 0 0.143"/>
    <parent link="link4"/>
    <child link="link5"/>
    <axis xyz="0 1 0"/>
    <limit effort="1000" lower="-2.0943951023931953" upper="2.0943951023931953" velocity="9.42477796076938"/>
    <dynamics damping="0.7" friction="0.0"/>
  </joint>
  <!-- joint 6 -->
  <joint name="joint6" type="revolute">
    <origin rpy="0 0 0" xyz="0 0 0.08"/>
    <parent link="link5"/>
    <child link="link6"/>
    <axis xyz="0 0 1"/>
    <limit effort="1000" lower="-6.283185307179586" upper="6.283185307179586" velocity="15.079644737231007"/>
    <dynamics damping="0.7" friction="0.0"/>
  </joint>
  <!-- tool frame - fixed frame -->
  <joint name="joint6-tool0" type="fixed">
    <parent link="link6"/>
    <child link="tool0"/>
    <origin rpy="0 -3.141592653589793 -1.5707963267948966" xyz="0 0 -0.115"/>
  </joint>
  <!-- END JOINTS -->
  <ros2_control name="denso_control" type="system">
    <hardware>
      <plugin>ign_ros2_control/IgnitionSystem</plugin>
    </hardware>
    <joint name="joint1">
      <command_interface name="position">
        <param name="min">-2.9670597283903604</param>
        <param name="max">2.9670597283903604</param>
      </command_interface>
      <state_interface name="position">
        <!-- initial position for the FakeSystem and simulation -->
        <param name="initial_value">0.0</param>
      </state_interface>
      <state_interface name="velocity"/>
      <state_interface name="effort"/>
    </joint>
    <joint name="joint2">
      <command_interface name="position">
        <param name="min">-1.7453292519943295</param>
        <param name="max">2.356194490192345</param>
      </command_interface>
      <state_interface name="position">
        <!-- initial position for the FakeSystem and simulation -->
        <param name="initial_value">0.0</param>
      </state_interface>
      <state_interface name="velocity"/>
      <state_interface name="effort"/>
    </joint>
    <joint name="joint3">
      <command_interface name="position">
        <param name="min">-2.3736477827122884</param>
        <param name="max">2.670353755551324</param>
      </command_interface>
      <state_interface name="position">
        <!-- initial position for the FakeSystem and simulation -->
        <param name="initial_value">1.57</param>
      </state_interface>
      <state_interface name="velocity"/>
      <state_interface name="effort"/>
    </joint>
    <joint name="joint4">
      <command_interface name="position">
        <param name="min">-4.71238898038469</param>
        <param name="max">4.71238898038469</param>
      </command_interface>
      <state_interface name="position">
        <!-- initial position for the FakeSystem and simulation -->
        <param name="initial_value">0.0</param>
      </state_interface>
      <state_interface name="velocity"/>
      <state_interface name="effort"/>
    </joint>
    <joint name="joint5">
      <command_interface name="position">
        <param name="min">-2.0943951023931953</param>
        <param name="max">2.0943951023931953</param>
      </command_interface>
      <state_interface name="position">
        <!-- initial position for the FakeSystem and simulation -->
        <param name="initial_value">0.0</param>
      </state_interface>
      <state_interface name="velocity"/>
      <state_interface name="effort"/>
    </joint>
    <joint name="joint6">
      <command_interface name="position">
        <param name="min">-6.283185307179586</param>
        <param name="max">6.283185307179586</param>
      </command_interface>
      <state_interface name="position">
        <!-- initial position for the FakeSystem and simulation -->
        <param name="initial_value">0.0</param>
      </state_interface>
      <state_interface name="velocity"/>
      <state_interface name="effort"/>
    </joint>
    <!-- Transmission -->
    <transmission name="transmission">
      <plugin>transmission_interface/SimpleTransmission</plugin>
      <joint name="joint1" role="revolute"/>
      <joint name="joint2" role="revolute"/>
      <joint name="joint3" role="revolute"/>
      <joint name="joint4" role="revolute"/>
      <joint name="joint5" role="revolute"/>
      <joint name="joint6" role="revolute"/>
    </transmission>
  </ros2_control>
  <gazebo>
    <!-- Joint state publisher -->
    <plugin filename="ign_ros2_control-system" name="ign_ros2_control::IgnitionROS2ControlPlugin">
      <parameters>/home/weizan/Projects/garment_ws/install/denso_robot_bringup/share/denso_robot_bringup/config/denso_robot_gazebo_controllers.yaml</parameters>
    </plugin>
  </gazebo>
</robot>
